/**
 * ErrorBoundary Component Tests
 * Testing error handling and fallback UI
 */

import React from 'react'
import { render, screen } from '@testing-library/react'
import { ErrorBoundary } from '@/components/shared/ErrorBoundary'

// Mock console.error to avoid noise in test output
const originalError = console.error
beforeAll(() => {
  console.error = jest.fn()
})

afterAll(() => {
  console.error = originalError
})

// Component that throws an error for testing
const ThrowError = ({ shouldThrow }: { shouldThrow: boolean }) => {
  if (shouldThrow) {
    throw new Error('Test error')
  }
  return <div>No error</div>
}

describe('ErrorBoundary', () => {
  beforeEach(() => {
    jest.clearAllMocks()
  })

  it('renders children when there is no error', () => {
    render(
      <ErrorBoundary>
        <ThrowError shouldThrow={false} />
      </ErrorBoundary>
    )

    expect(screen.getByText('No error')).toBeInTheDocument()
  })

  it('renders error UI when there is an error', () => {
    render(
      <ErrorBoundary>
        <ThrowError shouldThrow={true} />
      </ErrorBoundary>
    )

    expect(screen.getByText('Something went wrong')).toBeInTheDocument()
    expect(screen.getByText('We encountered an unexpected error.')).toBeInTheDocument()
    expect(screen.getByRole('button', { name: /try again/i })).toBeInTheDocument()
  })

  it('renders custom fallback when provided', () => {
    const customFallback = <div>Custom error message</div>

    render(
      <ErrorBoundary fallback={customFallback}>
        <ThrowError shouldThrow={true} />
      </ErrorBoundary>
    )

    expect(screen.getByText('Custom error message')).toBeInTheDocument()
    expect(screen.queryByText('Something went wrong')).not.toBeInTheDocument()
  })

  it('calls onError callback when error occurs', () => {
    const onError = jest.fn()

    render(
      <ErrorBoundary onError={onError}>
        <ThrowError shouldThrow={true} />
      </ErrorBoundary>
    )

    expect(onError).toHaveBeenCalledWith(
      expect.objectContaining({ message: 'Test error' }),
      expect.objectContaining({ componentStack: expect.any(String) })
    )
  })

  it('resets error state when Try Again is clicked', () => {
    const { rerender } = render(
      <ErrorBoundary>
        <ThrowError shouldThrow={true} />
      </ErrorBoundary>
    )

    expect(screen.getByText('Something went wrong')).toBeInTheDocument()

    // Click try again
    const tryAgainButton = screen.getByRole('button', { name: /try again/i })
    tryAgainButton.click()

    // Re-render with no error
    rerender(
      <ErrorBoundary>
        <ThrowError shouldThrow={false} />
      </ErrorBoundary>
    )

    expect(screen.getByText('No error')).toBeInTheDocument()
    expect(screen.queryByText('Something went wrong')).not.toBeInTheDocument()
  })
}) 